Workbook

Sheet Resumen
A1: Verificación de Atlas Estructuras 3D contra problemas resueltos
A2: Informe generado el 05/10/2026. Cada hoja «Ej …» recrea un ejercicio, compara la solución de libro (o la fórmula cerrada) con el resultado del programa y muestra las fórmulas.
A4: Resultado global
A5: Ejercicios que verifican (verifican | total) | E5: =COUNTIF(G8:G52,"VERIFICA") | F5: =ROWS(G8:G52)
A6: Comprobaciones dentro de tolerancia (dentro | total) | E6: =SUM(F8:F52) | F6: =SUM(E8:E52)
A7: ID | B7: Tipo | C7: Ejercicio | D7: Fuente | E7: Comprobaciones | F7: Dentro de tolerancia | G7: Estado
A8: A01 | B8: Resultado publicado | C8: Cercha plana de 3 barras (carga horizontal) | D8: Prof. R. Austin, Univ. de Maryland, ENCE 353 · «Direct Stiffness Method» (apuntes de cátedra) | E8: ='Ej A01'!E22 | F8: ='Ej A01'!D22 | G8: =IF(F8=E8,"VERIFICA","DIFIERE")
A9: A02 | B9: Resultado publicado | C9: Cercha plana de 5 barras (cuadrado con diagonal) | D9: Prof. R. Austin, Univ. de Maryland, ENCE 353 · «Direct Stiffness Method» (apuntes de cátedra) | E9: ='Ej A02'!E25 | F9: ='Ej A02'!D25 | G9: =IF(F9=E9,"VERIFICA","DIFIERE")
A10: A03 | B10: Resultado publicado | C10: Cercha plana de 6 barras (cuadrado con dos diagonales) | D10: Prof. R. Austin, Univ. de Maryland, ENCE 353 · «Direct Stiffness Method» (apuntes de cátedra) | E10: ='Ej A03'!E27 | F10: ='Ej A03'!D27 | G10: =IF(F10=E10,"VERIFICA","DIFIERE")
A11: A04 | B11: Resultado publicado | C11: Emparrillado en L empotrado en ambos extremos (flexión + torsión) | D11: Univ. de Memphis, CIVL 7117 · capítulo 5b, ejemplo de emparrillado (apuntes de cátedra) | E11: ='Ej A04'!E31 | F11: ='Ej A04'!D31 | G11: =IF(F11=E11,"VERIFICA","DIFIERE")
A12: A05 | B12: Resultado publicado | C12: Barra traccionada IPB 120: resistencia por fluencia (ejemplo INTI-CIRSOC 4) | D12: INTI-CIRSOC · «Ejemplos de aplicación del Reglamento CIRSOC 301-EL» (Ejemplos 4, 5 y 6) | E12: ='Ej A05'!E24 | F12: ='Ej A05'!D24 | G12: =IF(F12=E12,"VERIFICA","DIFIERE")
A13: A06 | B13: Resultado publicado | C13: Viga IPE 500 de 16 m: esfuerzos mayorados 1,2D + 1,6L (ejemplo INTI-CIRSOC 5) | D13: INTI-CIRSOC · «Ejemplos de aplicación del Reglamento CIRSOC 301-EL» (Ejemplos 4, 5 y 6) | E13: ='Ej A06'!E26 | F13: ='Ej A06'!D26 | G13: =IF(F13=E13,"VERIFICA","DIFIERE")
A14: A07 | B14: Resultado publicado | C14: Viga PNI 300 de 10 m: momento mayorado y resistencia φb·Mp (ejemplo INTI-CIRSOC 6) | D14: INTI-CIRSOC · «Ejemplos de aplicación del Reglamento CIRSOC 301-EL» (Ejemplos 4, 5 y 6) | E14: ='Ej A07'!E24 | F14: ='Ej A07'!D24 | G14: =IF(F14=E14,"VERIFICA","DIFIERE")
A15: A08 | B15: Resultado publicado | C15: Columna W14×74, A36, KL = 20 ft: resistencia a compresión (apuntes MSU, ej. 3.2) | D15: Michigan State Univ., CE 405 «Design of Steel Structures», cap. 3 «Compression members» (ejemplos 3.2 y 3.4, AISC-LRFD 1999) | E15: ='Ej A08'!E36 | F15: ='Ej A08'!D36 | G15: =IF(F15=E15,"VERIFICA","DIFIERE")
A16: A09 | B16: Resultado publicado | C16: Columna W14×132, Fy = 50 ksi, longitudes distintas por eje (apuntes MSU, ej. 3.4) | D16: Michigan State Univ., CE 405 «Design of Steel Structures», cap. 3 «Compression members» (ejemplos 3.2 y 3.4, AISC-LRFD 1999) | E16: ='Ej A09'!E37 | F16: ='Ej A09'!D37 | G16: =IF(F16=E16,"VERIFICA","DIFIERE")
A17: C01 | B17: Solución clásica | C17: Viga biapoyada con carga uniforme (D + L y combinaciones) | D17: Soluciones clásicas de resistencia de materiales y análisis estructural (tablas de vigas, método de pendiente-deflexión, método de los nudos, castigliano) | E17: ='Ej C01'!E27 | F17: ='Ej C01'!D27 | G17: =IF(F17=E17,"VERIFICA","DIFIERE")
A18: C02 | B18: Solución clásica | C18: Voladizo con carga puntual en el extremo | D18: Soluciones clásicas de resistencia de materiales y análisis estructural (tablas de vigas, método de pendiente-deflexión, método de los nudos, castigliano) | E18: ='Ej C02'!E23 | F18: ='Ej C02'!D23 | G18: =IF(F18=E18,"VERIFICA","DIFIERE")
A19: C03 | B19: Solución clásica | C19: Voladizo con carga uniforme | D19: Soluciones clásicas de resistencia de materiales y análisis estructural (tablas de vigas, método de pendiente-deflexión, método de los nudos, castigliano) | E19: ='Ej C03'!E21 | F19: ='Ej C03'!D21 | G19: =IF(F19=E19,"VERIFICA","DIFIERE")
A20: C04 | B20: Solución clásica | C20: Viga biempotrada con carga uniforme | D20: Soluciones clásicas de resistencia de materiales y análisis estructural (tablas de vigas, método de pendiente-deflexión, método de los nudos, castigliano) | E20: ='Ej C04'!E21 | F20: ='Ej C04'!D21 | G20: =IF(F20=E20,"VERIFICA","DIFIERE")
A21: C05 | B21: Solución clásica | C21: Viga continua de dos tramos iguales con carga uniforme | D21: Soluciones clásicas de resistencia de materiales y análisis estructural (tablas de vigas, método de pendiente-deflexión, método de los nudos, castigliano) | E21: ='Ej C05'!E22 | F21: ='Ej C05'!D22 | G21: =IF(F21=E21,"VERIFICA","DIFIERE")
A22: C06 | B22: Solución clásica | C22: Viga empotrada–apoyada con carga uniforme | D22: Soluciones clásicas de resistencia de materiales y análisis estructural (tablas de vigas, método de pendiente-deflexión, método de los nudos, castigliano) | E22: ='Ej C06'!E21 | F22: ='Ej C06'!D21 | G22: =IF(F22=E22,"VERIFICA","DIFIERE")
A23: C07 | B23: Solución clásica | C23: Viga Gerber (articulación intermedia) | D23: Soluciones clásicas de resistencia de materiales y análisis estructural (tablas de vigas, método de pendiente-deflexión, método de los nudos, castigliano) | E23: ='Ej C07'!E23 | F23: ='Ej C07'!D23 | G23: =IF(F23=E23,"VERIFICA","DIFIERE")
A24: C08 | B24: Solución clásica | C24: Reticulado plano triangular (método de los nudos) | D24: Soluciones clásicas de resistencia de materiales y análisis estructural (tablas de vigas, método de pendiente-deflexión, método de los nudos, castigliano) | E24: ='Ej C08'!E26 | F24: ='Ej C08'!D26 | G24: =IF(F24=E24,"VERIFICA","DIFIERE")
A25: C09 | B25: Solución clásica | C25: Reticulado espacial: trípode con carga vertical y horizontal | D25: Soluciones clásicas de resistencia de materiales y análisis estructural (tablas de vigas, método de pendiente-deflexión, método de los nudos, castigliano) | E25: ='Ej C09'!E28 | F25: ='Ej C09'!D28 | G25: =IF(F25=E25,"VERIFICA","DIFIERE")
A26: C10 | B26: Solución clásica | C26: Pórtico plano articulado en la base con carga lateral | D26: Soluciones clásicas de resistencia de materiales y análisis estructural (tablas de vigas, método de pendiente-deflexión, método de los nudos, castigliano) | E26: ='Ej C10'!E29 | F26: ='Ej C10'!D29 | G26: =IF(F26=E26,"VERIFICA","DIFIERE")
A27: C11 | B27: Solución clásica | C27: Pórtico plano empotrado en la base con carga lateral | D27: Soluciones clásicas de resistencia de materiales y análisis estructural (tablas de vigas, método de pendiente-deflexión, método de los nudos, castigliano) | E27: ='Ej C11'!E31 | F27: ='Ej C11'!D31 | G27: =IF(F27=E27,"VERIFICA","DIFIERE")
A28: C12 | B28: Solución clásica | C28: Pórtico plano empotrado con carga uniforme en el dintel | D28: Soluciones clásicas de resistencia de materiales y análisis estructural (tablas de vigas, método de pendiente-deflexión, método de los nudos, castigliano) | E28: ='Ej C12'!E29 | F28: ='Ej C12'!D29 | G28: =IF(F28=E28,"VERIFICA","DIFIERE")
A29: C13 | B29: Solución clásica | C29: Ménsula en L en el espacio (flexión + torsión) | D29: Soluciones clásicas de resistencia de materiales y análisis estructural (tablas de vigas, método de pendiente-deflexión, método de los nudos, castigliano) | E29: ='Ej C13'!E27 | F29: ='Ej C13'!D27 | G29: =IF(F29=E29,"VERIFICA","DIFIERE")
A30: C14 | B30: Solución clásica | C30: Columna en voladizo con cargas horizontales en los dos ejes | D30: Soluciones clásicas de resistencia de materiales y análisis estructural (tablas de vigas, método de pendiente-deflexión, método de los nudos, castigliano) | E30: ='Ej C14'!E25 | F30: ='Ej C14'!D25 | G30: =IF(F30=E30,"VERIFICA","DIFIERE")
A31: C15 | B31: Solución clásica | C31: Barra girada (ángulo β): eje fuerte, débil e inclinado | D31: Soluciones clásicas de resistencia de materiales y análisis estructural (tablas de vigas, método de pendiente-deflexión, método de los nudos, castigliano) | E31: ='Ej C15'!E22 | F31: ='Ej C15'!D22 | G31: =IF(F31=E31,"VERIFICA","DIFIERE")
A32: C16 | B32: Solución clásica | C32: Voladizo inclinado 30° con carga vertical | D32: Soluciones clásicas de resistencia de materiales y análisis estructural (tablas de vigas, método de pendiente-deflexión, método de los nudos, castigliano) | E32: ='Ej C16'!E29 | F32: ='Ej C16'!D29 | G32: =IF(F32=E32,"VERIFICA","DIFIERE")
A33: C17 | B33: Solución clásica | C33: Peso propio del perfil | D33: Soluciones clásicas de resistencia de materiales y análisis estructural (tablas de vigas, método de pendiente-deflexión, método de los nudos, castigliano) | E33: ='Ej C17'!E21 | F33: ='Ej C17'!D21 | G33: =IF(F33=E33,"VERIFICA","DIFIERE")
A34: N01 | B34: Solución clásica | C34: Carga y momento puntuales dentro del tramo (viga biapoyada, plano fuerte y débil) | D34: Soluciones clásicas: Timoshenko «Resistencia de materiales» y «Theory of Elastic Stability» (Timoshenko & Gere), Roark «Formulas for Stress and Strain», método de pendiente-deflexión, Ghali & Neville «Structural Analysis» (efectos térmicos y asentamientos) | E34: ='Ej N01'!E40 | F34: ='Ej N01'!D40 | G34: =IF(F34=E34,"VERIFICA","DIFIERE")
A35: N02 | B35: Solución clásica | C35: Carga uniforme parcial (viga biapoyada) | D35: Soluciones clásicas: Timoshenko «Resistencia de materiales» y «Theory of Elastic Stability» (Timoshenko & Gere), Roark «Formulas for Stress and Strain», método de pendiente-deflexión, Ghali & Neville «Structural Analysis» (efectos térmicos y asentamientos) | E35: ='Ej N02'!E33 | F35: ='Ej N02'!D33 | G35: =IF(F35=E35,"VERIFICA","DIFIERE")
A36: N03 | B36: Solución clásica | C36: Carga trapezoidal sobre toda la luz (uniforme + triangular) | D36: Soluciones clásicas: Timoshenko «Resistencia de materiales» y «Theory of Elastic Stability» (Timoshenko & Gere), Roark «Formulas for Stress and Strain», método de pendiente-deflexión, Ghali & Neville «Structural Analysis» (efectos térmicos y asentamientos) | E36: ='Ej N03'!E27 | F36: ='Ej N03'!D27 | G36: =IF(F36=E36,"VERIFICA","DIFIERE")
A37: N04 | B37: Solución clásica | C37: Temperatura: variación uniforme y gradiente en el canto | D37: Soluciones clásicas: Timoshenko «Resistencia de materiales» y «Theory of Elastic Stability» (Timoshenko & Gere), Roark «Formulas for Stress and Strain», método de pendiente-deflexión, Ghali & Neville «Structural Analysis» (efectos térmicos y asentamientos) | E37: ='Ej N04'!E30 | F37: ='Ej N04'!D30 | G37: =IF(F37=E37,"VERIFICA","DIFIERE")
A38: N05 | B38: Solución clásica | C38: Apoyos elásticos: resorte vertical y resorte de giro | D38: Soluciones clásicas: Timoshenko «Resistencia de materiales» y «Theory of Elastic Stability» (Timoshenko & Gere), Roark «Formulas for Stress and Strain», método de pendiente-deflexión, Ghali & Neville «Structural Analysis» (efectos térmicos y asentamientos) | E38: ='Ej N05'!E36 | F38: ='Ej N05'!D36 | G38: =IF(F38=E38,"VERIFICA","DIFIERE")
A39: N06 | B39: Solución clásica | C39: Asentamientos impuestos de apoyo | D39: Soluciones clásicas: Timoshenko «Resistencia de materiales» y «Theory of Elastic Stability» (Timoshenko & Gere), Roark «Formulas for Stress and Strain», método de pendiente-deflexión, Ghali & Neville «Structural Analysis» (efectos térmicos y asentamientos) | E39: ='Ej N06'!E39 | F39: ='Ej N06'!D39 | G39: =IF(F39=E39,"VERIFICA","DIFIERE")
A40: N07 | B40: Solución clásica | C40: Uniones semirrígidas (resorte de giro en el extremo de la barra) | D40: Soluciones clásicas: Timoshenko «Resistencia de materiales» y «Theory of Elastic Stability» (Timoshenko & Gere), Roark «Formulas for Stress and Strain», método de pendiente-deflexión, Ghali & Neville «Structural Analysis» (efectos térmicos y asentamientos) | E40: ='Ej N07'!E33 | F40: ='Ej N07'!D33 | G40: =IF(F40=E40,"VERIFICA","DIFIERE")
A41: N08 | B41: Solución clásica | C41: Deformación por corte (Timoshenko): voladizo y viga corta | D41: Soluciones clásicas: Timoshenko «Resistencia de materiales» y «Theory of Elastic Stability» (Timoshenko & Gere), Roark «Formulas for Stress and Strain», método de pendiente-deflexión, Ghali & Neville «Structural Analysis» (efectos térmicos y asentamientos) | E41: ='Ej N08'!E26 | F41: ='Ej N08'!D26 | G41: =IF(F41=E41,"VERIFICA","DIFIERE")
...

Sheet Notas
A1: Notas, alcance y límites de la verificación
A3: Cómo leer este informe
A4: Qué se compara | B4: Cada ejercicio se arma en el programa (nudos, barras, cargas y combinaciones), se calcula con el mismo motor de la app y se compara el resultado con (a) un número impreso en un libro o apunte, o (b) una fórmula cerrada que se escribe en la hoja con sintaxis de Excel. La columna «Programa» pega el valor que dio la app; la columna «Teoría» es una fórmula viva que se recalcula si cambiás los datos.
A5: Tolerancias | B5: Se fijaron según el origen de la teoría: 0,01 % para fórmulas exactas (el único error es el redondeo numérico), 0,1 a 0,5 % cuando el libro redondea sus cifras, y 1,5 a 2 % donde la fuente es una aproximación (por ejemplo el momento plástico con el Zx de tabla). Están en las columnas «Tol.» y se pueden cambiar.
A6: Colores | B6: Azul sobre fondo amarillo: dato ingresado o valor entregado por el programa. Negro: fórmula de Excel. «Publicado» marca las filas cuyo número está impreso en la fuente; «Fórmula» las que se obtienen de una expresión cerrada.
A7: Dónde reproducirlo | B7: En la app, botón «Ejercicios» (barra superior): lista los 45 ejercicios con su estado, permite cargar cada uno en el lienzo, calcularlo y ver la comparación en la pestaña «Verificación», y volver a correr todo.
A9: Fuentes con resultado publicado
A10: Prof. R. Austin, Univ. de Maryland — ENCE 353, «Direct Stiffness Method» | B10: https://user.eng.umd.edu/~austin/ence353.d/lecture-material2025/direct-stiffness-method.pdf
B11: Tres cerchas planas (A01–A03). Los desplazamientos y axiles publicados coinciden con el programa hasta el redondeo de la fuente.
A12: Univ. de Memphis — CIVL 7117, capítulo 5b (emparrillado) | B12: https://www.ce.memphis.edu/7117/notes/presentations/chapter_05b.pdf
B13: Emparrillado en L con flexión y torsión (A04). La fuente redondea (torsor 1,50 kN·m; la solución exacta es 1,646). Se agregaron filas con la solución exacta deducida por compatibilidad y verificada con PyNite.
A14: INTI-CIRSOC — Ejemplos de aplicación del Reglamento CIRSOC 301-EL | B14: https://www.inti.gob.ar/assets/uploads/files/cirsoc/EJEMPLOS%202/EJEMPLOS%202.2/1_%20ejemplos_301.pdf
B15: Ejemplos 4 (barra traccionada IPB 120, φtPn = 719 kN), 5 (viga IPE 500 de 16 m, Mu = 332,8 kN·m, Vu = 41,6 kN) y 6 (viga PNI 300, Mu = 275 kN·m, φbMp = 161,16 kN·m): A05–A07.
A16: Michigan State Univ. — CE 405 «Design of Steel Structures», cap. 3 | B16: https://www.egr.msu.edu/~harichan/classes/ce405/chap3.pdf
B17: Ejemplos 3.2 (W14×74, φcPn = 408 kip) y 3.4 (W14×132, φcPn ≈ 1 300 kip), con el método AISC-LRFD 1999 (φc = 0,85, parámetro λc) en que se basa el CIRSOC 301-2005: A08 y A09.
A18: Funciones nuevas de la versión 2 (N01–N15) | B18: Soluciones cerradas de la teoría de vigas: viga-columna de Timoshenko & Gere («Theory of Elastic Stability»: tan kL, sec u, carga crítica de Engesser con corte), resistencia de materiales de Timoshenko y Roark (cargas puntuales, parciales, triangulares, momentos puntuales, deformación por corte), pendiente-deflexión con resortes de giro (Monforton & Wu), y Ghali & Neville («Structural Analysis») para temperatura y asentamientos. Las fórmulas se escribieron de memoria como resultados estándar y no se transcribieron de una página concreta: que coincidan con el programa a ~1e-8 sólo ocurre si las dos derivaciones (la del elemento exacto y la fórmula cerrada) son correctas. N16 es un contraste con otro programa (PyNite FEA 3.2, análisis P-Δ con las columnas divididas en 16 elementos) sobre un pórtico plano con 800 kN por columna: el desplazamiento horizontal de segundo orden (5,8115 mm, +13 % sobre el primer orden) coincide en 4 decimales y los momentos de base difieren ≈0,002 %; el descenso vertical difiere 0,07 % porque el elemento exacto no incluye el acortamiento por arqueo.
A19: Límite de N15 | B19: El momento máximo con deformación por corte se dedujo de la misma ecuación diferencial que usa el elemento (M″ + κM = r·w); confirma la implementación numérica pero no es una fuente independiente. Sí es independiente y clásica la carga crítica Pcr = Pe/(1 + Pe/G·As), con la que la fórmula es coherente.
A20: Constantes escritas de memoria | B20: En N09, N11 y N12 (marcados «Fórmulas del Reglamento») las constantes del LRFD-99 / CIRSOC 301-2005 se escribieron de memoria: tope Cb ≤ 2,3; λp = 0,38√(E/Fy); λr = 0,95√(kc·E/FL) y FL = Fy − 114 MPa para perfiles soldados; límite 0,64√(kc·E/Fy) y Qs = 1,415 − 0,65·λ·√(Fy/E)/√kc en compresión; kc = 4/√(h/tw). El ejercicio detecta que el programa las aplique como están escritas, pero NO garantiza que coincidan con el texto del Reglamento: hay que cotejarlas con el CIRSOC 301-2005 antes de usar el resultado en un proyecto.
A21: Cómo se leyeron | B21: Los PDF se leyeron con un lector automático que devuelve resúmenes. Para no depender de una transcripción, los números usados se recalcularon a mano: 719,1 kN = 0,9·235 MPa·3 400 mm²; Mu = (1,2·2 + 1,6·5)·16²/8 = 332,8 kN·m; Vu = 10,4·(8 − 4) = 41,6 kN; φbMp = 0,9·235·762 cm³ = 161,16 kN·m; φcPn de W14×74 = 0,85·21,8·21,99 = 407,5 kip.
A23: Lo que NO se pudo obtener
A24: Libros completos | B24: No se pudo leer el texto de Kassimali, McGuire–Gallagher–Ziemian ni de Hibbeler: los PDF disponibles son demasiado grandes para el lector o no están publicados en forma abierta. No se usaron copias pirata. Los problemas de esos libros no están en este informe.
A25: Apuntes bloqueados | B25: Las guías de la UTN Facultad Regional Mendoza (CIRSOC 301) y otros repositorios impiden el acceso automático (robots.txt); no se eludió la restricción. Del documento del INTI sólo se pudo verificar con confianza los ejemplos 4 a 6; el ejemplo 6 completo (PNI 300 con platabanda soldada) no se reproduce: aquí sólo se verifican Mu y φb·Mp del perfil solo. Las propiedades de las secciones armadas de la versión 2 (PS soldada, perfil + platabanda, cajón) se verifican aparte en N10.
A26: Pedido | B26: Si me pasás fotos o PDF de problemas resueltos de tus propios libros (con su resultado), los cargo del mismo modo y se agregan a este informe.
A28: Resultados que no coinciden exactamente (y por qué)
A29: A04 – torsor publicado | B29: La fuente da 1,50 kN·m y la solución exacta del problema es 1,646 kN·m (el programa y PyNite coinciden con la exacta). Diferencia atribuible al redondeo del apunte.
A30: A07 – momento plástico | B30: El programa estima el módulo plástico Zx con la geometría simplificada de la sección y da 768 cm³ para el PNI 300; la tabla indica 762 cm³ (+0,8 %). Es una aproximación del programa, no un error del solver.
A31: A08 y A09 – columnas | B31: La diferencia de −0,17 % y −0,25 % respecto de lo impreso viene del redondeo del libro y de usar el radio de giro calculado (√(I/A)) en lugar del tabulado.
A32: Perfiles IPE – Zx | B32: Con la geometría simplificada (sin el acuerdo alma-ala) el programa subestima el módulo plástico respecto de la tabla en torno de 4 a 6 % (hoja «Control Zx IPE»). Es del lado seguro (reduce φbMp), pero hace que las barras IPE den en flexión un r algo mayor que el real. Se informa como observación; el catálogo de la app no se modificó.
A34: Límites del programa que esta verificación NO cubre
A35: Análisis | B35: Segundo orden opcional por iteración sobre el axil de cada barra con funciones de estabilidad exactas (P-Δ y P-δ). No incluye imperfecciones iniciales ni cargas nocionales (la opción de rigidez reducida DAM no agrega nocionales), ni el acoplamiento axil-torsión, ni el alabeo restringido en el análisis (el Cw sólo interviene en la resistencia). Material elástico lineal; apoyos lineales.
A36: Resistencia | B36: Tracción: sólo fluencia de la sección bruta (sin rotura de la sección neta). Flexocompresión con alma esbelta y cajones de almas esbeltas: aproximados. Sin uniones, anclajes, excentricidades, fatiga ni fuego. J y Cw de los perfiles laminados son aproximados (J ≈ 1,3·Σbt³/3).
A37: Generadores de viento y sismo | B37: Los coeficientes de tabla (Cf, G, V, coeficiente sísmico C, pesos) los carga el usuario; el programa aplica las fórmulas de presión y reparto. Los generadores se probaron en la app (qz recalculado aparte, ΣF = C·W), pero no están en estos ejercicios; las combinaciones se verifican en N14 con los factores cargados en el propio ejercicio.
A38: Alcance de la prueba | B38: Un problema de libro sólo prueba los casos que cubre: estas 45 pruebas dan confianza razonable en el solver (desplazamientos, reacciones, esfuerzos, torsión, ejes locales, combinaciones, cargas de barra, resortes, asentamientos, uniones semirrígidas, deformación por corte y segundo orden) y en la implementación de las fórmulas de resistencia, pero no reemplazan la revisión del proyecto por un profesional.
A40: Prueba de sensibilidad (¿detectan los ejercicios un error?)
A41: Método | B41: Se alteró a propósito el código del programa, de a una modificación por vez, y se volvieron a correr los 45 ejercicios. Las 33 alteraciones fueron detectadas por al menos un ejercicio:
A42: φc 0,85→0,90 | B42: Detectado por: A08, A09, F01, F03, N11
A43: Lp 1,76→1,70 | B43: Detectado por: F02, F03, N12
A44: interacción 8/9→8/10 | B44: Detectado por: F03
A45: corte 0,6→0,5 (alma) | B45: Detectado por: F02
A46: curva de columna 0,658→0,66 | B46: Detectado por: A08, F01, N11
...

Sheet Control Zx IPE
A1: Módulo plástico Zx de los IPE: programa vs tabla
A2: Zx programa = b·tf·(h − tf) + tw·(h − 2tf)²/4 (geometría simplificada del programa; el tope 1,5·Sx no interviene en estos perfiles). Zx tabla = Wpl,y de las tablas de perfiles IPE.
A4: Perfil | B4: h (mm) | C4: b (mm) | D4: tw (mm) | E4: tf (mm) | F4: Wpl,y tabla (cm³) | G4: Zx programa (cm³) | H4: Programa / tabla − 1
A5: IPE 100 | B5: 100 | C5: 55 | D5: 4.1 | E5: 5.7 | F5: 39.4 | G5: =(C5*E5*(B5-E5)+D5*(B5-2*E5)^2/4)/1000 | H5: =G5/F5-1
A6: IPE 200 | B6: 200 | C6: 100 | D6: 5.6 | E6: 8.5 | F6: 220.6 | G6: =(C6*E6*(B6-E6)+D6*(B6-2*E6)^2/4)/1000 | H6: =G6/F6-1
A7: IPE 240 | B7: 240 | C7: 120 | D7: 6.2 | E7: 9.8 | F7: 366.6 | G7: =(C7*E7*(B7-E7)+D7*(B7-2*E7)^2/4)/1000 | H7: =G7/F7-1
A8: IPE 300 | B8: 300 | C8: 150 | D8: 7.1 | E8: 10.7 | F8: 628.4 | G8: =(C8*E8*(B8-E8)+D8*(B8-2*E8)^2/4)/1000 | H8: =G8/F8-1
A9: IPE 400 | B9: 400 | C9: 180 | D9: 8.6 | E9: 13.5 | F9: 1307 | G9: =(C9*E9*(B9-E9)+D9*(B9-2*E9)^2/4)/1000 | H9: =G9/F9-1
A11: Los valores de h, b, tw, tf y Wpl,y son de tabla (Wpl,y: catálogos de IPE EN 10365). La diferencia negativa indica que el programa es conservador en flexión.

Sheet Ej A01
A1: A01 · Cercha plana de 3 barras (carga horizontal)
A2: Resultado publicado. Fuente: Prof. R. Austin, Univ. de Maryland, ENCE 353 · «Direct Stiffness Method» (apuntes de cátedra)
A3: https://user.eng.umd.edu/~austin/ence353.d/lecture-material2025/direct-stiffness-method.pdf
A4: Enunciado. Cercha en el plano XZ: nudo 1 (0,0) articulado, nudo 2 (10,0) con apoyo móvil vertical, nudo 3 (0,10) libre con carga horizontal de 10. Las tres barras tienen E = A = 1. Se comparan desplazamientos y esfuerzos axiles publicados.
A6: DATOS DEL EJERCICIO
A7: # | B7: Dato | C7: Unidad | D7: Valor | K7: Símbolo | L7: Fórmula (texto)
A8: 1 | B8: Módulo elástico adoptado (EA = 1000 N) | C8: MPa | D8: 1000 | K8: E | L8: dato ingresado
A9: 2 | B9: Área de cada barra (la fuente adopta E = A = 1) | C9: mm² | D9: 1 | K9: A | L9: dato ingresado
A10: 3 | B10: Carga de la fuente (valor 10) | C10: kN | D10: 10 | K10: F | L10: dato ingresado
A11: 4 | B11: Lado del cuadrado de la fuente (valor 10) | C11: mm | D11: 10 | K11: a | L11: dato ingresado
A13: COMPARACIÓN: TEORÍA / DATO PUBLICADO vs PROGRAMA (Atlas Estructuras 3D)
A14: # | B14: Comprobación | C14: Unidad | D14: Teoría / publicado | E14: Programa | F14: Diferencia (prog. − teoría) | G14: Error relativo | H14: Tol. relativa | I14: Tol. absoluta | J14: Estado | K14: Origen | L14: Expresión de la teoría (texto) | M14: Dónde se lee en el programa | N14: Nota
A15: 1 | B15: Desplazamiento horizontal del nudo 2 | C15: mm | D15: =100 | E15: 100 | F15: =E15-D15 | G15: =IF(ABS(D15)>0.000000000001,F15/D15,"—") | H15: 1e-05 | I15: 1e-06 | J15: =IF(ABS(F15)<=MAX(H15*ABS(D15),I15),"OK","NO") | K15: Publicado | L15: 100 | M15: Desplazamiento Ux del nudo 2 · combinación «C1: 1,0·D + 1,0·Hx»
A16: 2 | B16: Desplazamiento horizontal del nudo 3 | C16: mm | D16: =482.843 | E16: 482.84271 | F16: =E16-D16 | G16: =IF(ABS(D16)>0.000000000001,F16/D16,"—") | H16: 2e-06 | I16: 1e-06 | J16: =IF(ABS(F16)<=MAX(H16*ABS(D16),I16),"OK","NO") | K16: Publicado | L16: 482.843 | M16: Desplazamiento Ux del nudo 3 · combinación «C1: 1,0·D + 1,0·Hx»
A17: 3 | B17: Desplazamiento vertical del nudo 3 | C17: mm | D17: =100 | E17: 100 | F17: =E17-D17 | G17: =IF(ABS(D17)>0.000000000001,F17/D17,"—") | H17: 1e-05 | I17: 1e-06 | J17: =IF(ABS(F17)<=MAX(H17*ABS(D17),I17),"OK","NO") | K17: Publicado | L17: 100 | M17: Desplazamiento Uz del nudo 3 · combinación «C1: 1,0·D + 1,0·Hx»
A18: 4 | B18: Esfuerzo axil barra 1 (1–2), tracción + | C18: kN | D18: =10 | E18: 10 | F18: =E18-D18 | G18: =IF(ABS(D18)>0.000000000001,F18/D18,"—") | H18: 1e-05 | I18: 1e-06 | J18: =IF(ABS(F18)<=MAX(H18*ABS(D18),I18),"OK","NO") | K18: Publicado | L18: 10 | M18: Barra 1, en x = 0.5·L, esfuerzo axil N (tracción +) · combinación «C1: 1,0·D + 1,0·Hx»
A19: 5 | B19: Esfuerzo axil barra 2 (1–3) | C19: kN | D19: =10 | E19: 10 | F19: =E19-D19 | G19: =IF(ABS(D19)>0.000000000001,F19/D19,"—") | H19: 1e-05 | I19: 1e-06 | J19: =IF(ABS(F19)<=MAX(H19*ABS(D19),I19),"OK","NO") | K19: Publicado | L19: 10 | M19: Barra 2, en x = 0.5·L, esfuerzo axil N (tracción +) · combinación «C1: 1,0·D + 1,0·Hx»
A20: 6 | B20: Esfuerzo axil barra 3 (2–3), compresión − | C20: kN | D20: =-14.142136 | E20: -14.142136 | F20: =E20-D20 | G20: =IF(ABS(D20)>0.000000000001,F20/D20,"—") | H20: 1e-05 | I20: 1e-06 | J20: =IF(ABS(F20)<=MAX(H20*ABS(D20),I20),"OK","NO") | K20: Publicado | L20: -14.142136 | M20: Barra 3, en x = 0.5·L, esfuerzo axil N (tracción +) · combinación «C1: 1,0·D + 1,0·Hx»
B22: Comprobaciones dentro de tolerancia | D22: =COUNTIF(J15:J20,"OK") | E22: =ROWS(J15:J20) | F22: =IF(D22=E22,"VERIFICA","DIFIERE")
B23: Azul = dato ingresado o valor que entregó el programa (pegado); negro = fórmula de Excel. El valor «Programa» es el resultado del motor de cálculo de la app para el mismo modelo.

Sheet Ej A02
A1: A02 · Cercha plana de 5 barras (cuadrado con diagonal)
A2: Resultado publicado. Fuente: Prof. R. Austin, Univ. de Maryland, ENCE 353 · «Direct Stiffness Method» (apuntes de cátedra)
A3: https://user.eng.umd.edu/~austin/ence353.d/lecture-material2025/direct-stiffness-method.pdf
A4: Enunciado. Cuadrado de lado 10 en el plano XZ con 5 barras: los cuatro lados (1–2, 1–3, 2–4 y 3–4) y la diagonal 1–4. Nudo 1 articulado, nudo 2 con apoyo móvil vertical. Cargas: 10 horizontal en el nudo 3 y 10 hacia abajo en el nudo 4. E = A = 1.
A6: DATOS DEL EJERCICIO
A7: # | B7: Dato | C7: Unidad | D7: Valor | K7: Símbolo | L7: Fórmula (texto)
A8: 1 | B8: Módulo elástico adoptado (EA = 1000 N) | C8: MPa | D8: 1000 | K8: E | L8: dato ingresado
A9: 2 | B9: Área de cada barra (la fuente adopta E = A = 1) | C9: mm² | D9: 1 | K9: A | L9: dato ingresado
A10: 3 | B10: Carga de la fuente (valor 10) | C10: kN | D10: 10 | K10: F | L10: dato ingresado
A11: 4 | B11: Lado del cuadrado de la fuente (valor 10) | C11: mm | D11: 10 | K11: a | L11: dato ingresado
A13: COMPARACIÓN: TEORÍA / DATO PUBLICADO vs PROGRAMA (Atlas Estructuras 3D)
A14: # | B14: Comprobación | C14: Unidad | D14: Teoría / publicado | E14: Programa | F14: Diferencia (prog. − teoría) | G14: Error relativo | H14: Tol. relativa | I14: Tol. absoluta | J14: Estado | K14: Origen | L14: Expresión de la teoría (texto) | M14: Dónde se lee en el programa | N14: Nota
A15: 1 | B15: Desplazamiento horizontal del nudo 3 | C15: mm | D15: =582.843 | E15: 582.84271 | F15: =E15-D15 | G15: =IF(ABS(D15)>0.000000000001,F15/D15,"—") | H15: 2e-06 | I15: 1e-06 | J15: =IF(ABS(F15)<=MAX(H15*ABS(D15),I15),"OK","NO") | K15: Publicado | L15: 582.843 | M15: Desplazamiento Ux del nudo 3 · combinación «C1: 1,0·D + 1,0·Hx»
A16: 2 | B16: Desplazamiento vertical del nudo 3 | C16: mm | D16: =0 | E16: 1.7763568e-15 | F16: =E16-D16 | G16: =IF(ABS(D16)>0.000000000001,F16/D16,"—") | H16: 1e-05 | I16: 1e-06 | J16: =IF(ABS(F16)<=MAX(H16*ABS(D16),I16),"OK","NO") | K16: Publicado | L16: 0 | M16: Desplazamiento Uz del nudo 3 · combinación «C1: 1,0·D + 1,0·Hx»
A17: 3 | B17: Desplazamiento horizontal del nudo 4 | C17: mm | D17: =482.843 | E17: 482.84271 | F17: =E17-D17 | G17: =IF(ABS(D17)>0.000000000001,F17/D17,"—") | H17: 2e-06 | I17: 1e-06 | J17: =IF(ABS(F17)<=MAX(H17*ABS(D17),I17),"OK","NO") | K17: Publicado | L17: 482.843 | M17: Desplazamiento Ux del nudo 4 · combinación «C1: 1,0·D + 1,0·Hx»
A18: 4 | B18: Desplazamiento vertical del nudo 4 | C18: mm | D18: =-200 | E18: -200 | F18: =E18-D18 | G18: =IF(ABS(D18)>0.000000000001,F18/D18,"—") | H18: 1e-05 | I18: 1e-06 | J18: =IF(ABS(F18)<=MAX(H18*ABS(D18),I18),"OK","NO") | K18: Publicado | L18: -200 | M18: Desplazamiento Uz del nudo 4 · combinación «C1: 1,0·D + 1,0·Hx»
A19: 5 | B19: Axil barra 1 (1–2) | C19: kN | D19: =0 | E19: -4.2885048e-16 | F19: =E19-D19 | G19: =IF(ABS(D19)>0.000000000001,F19/D19,"—") | H19: 1e-05 | I19: 1e-06 | J19: =IF(ABS(F19)<=MAX(H19*ABS(D19),I19),"OK","NO") | K19: Publicado | L19: 0 | M19: Barra 1, en x = 0.5·L, esfuerzo axil N (tracción +) · combinación «C1: 1,0·D + 1,0·Hx»
A20: 6 | B20: Axil barra 2 (1–3) | C20: kN | D20: =0 | E20: 1.7763568e-16 | F20: =E20-D20 | G20: =IF(ABS(D20)>0.000000000001,F20/D20,"—") | H20: 1e-05 | I20: 1e-06 | J20: =IF(ABS(F20)<=MAX(H20*ABS(D20),I20),"OK","NO") | K20: Publicado | L20: 0 | M20: Barra 2, en x = 0.5·L, esfuerzo axil N (tracción +) · combinación «C1: 1,0·D + 1,0·Hx»
A21: 7 | B21: Axil barra 3 (2–4) | C21: kN | D21: =-20 | E21: -20 | F21: =E21-D21 | G21: =IF(ABS(D21)>0.000000000001,F21/D21,"—") | H21: 1e-05 | I21: 1e-06 | J21: =IF(ABS(F21)<=MAX(H21*ABS(D21),I21),"OK","NO") | K21: Publicado | L21: -20 | M21: Barra 3, en x = 0.5·L, esfuerzo axil N (tracción +) · combinación «C1: 1,0·D + 1,0·Hx»
A22: 8 | B22: Axil barra 4 (3–4) | C22: kN | D22: =-10 | E22: -10 | F22: =E22-D22 | G22: =IF(ABS(D22)>0.000000000001,F22/D22,"—") | H22: 1e-05 | I22: 1e-06 | J22: =IF(ABS(F22)<=MAX(H22*ABS(D22),I22),"OK","NO") | K22: Publicado | L22: -10 | M22: Barra 4, en x = 0.5·L, esfuerzo axil N (tracción +) · combinación «C1: 1,0·D + 1,0·Hx»
A23: 9 | B23: Axil barra 5 (diagonal 1–4) | C23: kN | D23: =14.142136 | E23: 14.142136 | F23: =E23-D23 | G23: =IF(ABS(D23)>0.000000000001,F23/D23,"—") | H23: 1e-05 | I23: 1e-06 | J23: =IF(ABS(F23)<=MAX(H23*ABS(D23),I23),"OK","NO") | K23: Publicado | L23: 14.142136 | M23: Barra 5, en x = 0.5·L, esfuerzo axil N (tracción +) · combinación «C1: 1,0·D + 1,0·Hx»
B25: Comprobaciones dentro de tolerancia | D25: =COUNTIF(J15:J23,"OK") | E25: =ROWS(J15:J23) | F25: =IF(D25=E25,"VERIFICA","DIFIERE")
B26: Azul = dato ingresado o valor que entregó el programa (pegado); negro = fórmula de Excel. El valor «Programa» es el resultado del motor de cálculo de la app para el mismo modelo.

Sheet Ej A03
A1: A03 · Cercha plana de 6 barras (cuadrado con dos diagonales)
A2: Resultado publicado. Fuente: Prof. R. Austin, Univ. de Maryland, ENCE 353 · «Direct Stiffness Method» (apuntes de cátedra)
A3: https://user.eng.umd.edu/~austin/ence353.d/lecture-material2025/direct-stiffness-method.pdf
A4: Enunciado. Igual al ejercicio A02 con una segunda diagonal 2–3 (seis barras). Mismos apoyos, cargas y E = A = 1. Se comparan los desplazamientos y los esfuerzos axiles publicados (la fuente trunca los axiles a dos decimales).
A6: DATOS DEL EJERCICIO
A7: # | B7: Dato | C7: Unidad | D7: Valor | K7: Símbolo | L7: Fórmula (texto)
A8: 1 | B8: Módulo elástico adoptado (EA = 1000 N) | C8: MPa | D8: 1000 | K8: E | L8: dato ingresado
A9: 2 | B9: Área de cada barra (la fuente adopta E = A = 1) | C9: mm² | D9: 1 | K9: A | L9: dato ingresado
A10: 3 | B10: Carga de la fuente (valor 10) | C10: kN | D10: 10 | K10: F | L10: dato ingresado
A11: 4 | B11: Lado del cuadrado de la fuente (valor 10) | C11: mm | D11: 10 | K11: a | L11: dato ingresado
A13: COMPARACIÓN: TEORÍA / DATO PUBLICADO vs PROGRAMA (Atlas Estructuras 3D)
A14: # | B14: Comprobación | C14: Unidad | D14: Teoría / publicado | E14: Programa | F14: Diferencia (prog. − teoría) | G14: Error relativo | H14: Tol. relativa | I14: Tol. absoluta | J14: Estado | K14: Origen | L14: Expresión de la teoría (texto) | M14: Dónde se lee en el programa | N14: Nota
A15: 1 | B15: Desplazamiento horizontal del nudo 2 | C15: mm | D15: =60.3553 | E15: 60.355339 | F15: =E15-D15 | G15: =IF(ABS(D15)>0.000000000001,F15/D15,"—") | H15: 2e-06 | I15: 1e-06 | J15: =IF(ABS(F15)<=MAX(H15*ABS(D15),I15),"OK","NO") | K15: Publicado | L15: 60.3553 | M15: Desplazamiento Ux del nudo 2 · combinación «C1: 1,0·D + 1,0·Hx»
A16: 2 | B16: Desplazamiento horizontal del nudo 3 | C16: mm | D16: =291.421 | E16: 291.42136 | F16: =E16-D16 | G16: =IF(ABS(D16)>0.000000000001,F16/D16,"—") | H16: 5e-06 | I16: 1e-06 | J16: =IF(ABS(F16)<=MAX(H16*ABS(D16),I16),"OK","NO") | K16: Publicado | L16: 291.421 | M16: Desplazamiento Ux del nudo 3 · combinación «C1: 1,0·D + 1,0·Hx»
A17: 3 | B17: Desplazamiento vertical del nudo 3 | C17: mm | D17: =60.3553 | E17: 60.355339 | F17: =E17-D17 | G17: =IF(ABS(D17)>0.000000000001,F17/D17,"—") | H17: 2e-06 | I17: 1e-06 | J17: =IF(ABS(F17)<=MAX(H17*ABS(D17),I17),"OK","NO") | K17: Publicado | L17: 60.3553 | M17: Desplazamiento Uz del nudo 3 · combinación «C1: 1,0·D + 1,0·Hx»
A18: 4 | B18: Desplazamiento horizontal del nudo 4 | C18: mm | D18: =251.777 | E18: 251.7767 | F18: =E18-D18 | G18: =IF(ABS(D18)>0.000000000001,F18/D18,"—") | H18: 5e-06 | I18: 1e-06 | J18: =IF(ABS(F18)<=MAX(H18*ABS(D18),I18),"OK","NO") | K18: Publicado | L18: 251.777 | M18: Desplazamiento Ux del nudo 4 · combinación «C1: 1,0·D + 1,0·Hx»
A19: 5 | B19: Desplazamiento vertical del nudo 4 | C19: mm | D19: =-139.645 | E19: -139.64466 | F19: =E19-D19 | G19: =IF(ABS(D19)>0.000000000001,F19/D19,"—") | H19: 5e-06 | I19: 1e-06 | J19: =IF(ABS(F19)<=MAX(H19*ABS(D19),I19),"OK","NO") | K19: Publicado | L19: -139.645 | M19: Desplazamiento Uz del nudo 4 · combinación «C1: 1,0·D + 1,0·Hx»
A20: 6 | B20: Axil barra 1 (1–2) | C20: kN | D20: =6.0355 | E20: 6.0355339 | F20: =E20-D20 | G20: =IF(ABS(D20)>0.000000000001,F20/D20,"—") | H20: 0 | I20: 0.011 | J20: =IF(ABS(F20)<=MAX(H20*ABS(D20),I20),"OK","NO") | K20: Publicado | L20: 6.0355 | M20: Barra 1, en x = 0.5·L, esfuerzo axil N (tracción +) · combinación «C1: 1,0·D + 1,0·Hx»
A21: 7 | B21: Axil barra 2 (1–3) | C21: kN | D21: =6.0355 | E21: 6.0355339 | F21: =E21-D21 | G21: =IF(ABS(D21)>0.000000000001,F21/D21,"—") | H21: 0 | I21: 0.011 | J21: =IF(ABS(F21)<=MAX(H21*ABS(D21),I21),"OK","NO") | K21: Publicado | L21: 6.0355 | M21: Barra 2, en x = 0.5·L, esfuerzo axil N (tracción +) · combinación «C1: 1,0·D + 1,0·Hx»
A22: 8 | B22: Axil barra 3 (2–4) | C22: kN | D22: =-13.96 | E22: -13.964466 | F22: =E22-D22 | G22: =IF(ABS(D22)>0.000000000001,F22/D22,"—") | H22: 0 | I22: 0.011 | J22: =IF(ABS(F22)<=MAX(H22*ABS(D22),I22),"OK","NO") | K22: Publicado | L22: -13.96 | M22: Barra 3, en x = 0.5·L, esfuerzo axil N (tracción +) · combinación «C1: 1,0·D + 1,0·Hx»
A23: 9 | B23: Axil barra 4 (3–4) | C23: kN | D23: =-3.96 | E23: -3.9644661 | F23: =E23-D23 | G23: =IF(ABS(D23)>0.000000000001,F23/D23,"—") | H23: 0 | I23: 0.011 | J23: =IF(ABS(F23)<=MAX(H23*ABS(D23),I23),"OK","NO") | K23: Publicado | L23: -3.96 | M23: Barra 4, en x = 0.5·L, esfuerzo axil N (tracción +) · combinación «C1: 1,0·D + 1,0·Hx»
A24: 10 | B24: Axil barra 5 (diagonal 1–4) | C24: kN | D24: =5.60 | E24: 5.6066017 | F24: =E24-D24 | G24: =IF(ABS(D24)>0.000000000001,F24/D24,"—") | H24: 0 | I24: 0.011 | J24: =IF(ABS(F24)<=MAX(H24*ABS(D24),I24),"OK","NO") | K24: Publicado | L24: 5.60 | M24: Barra 5, en x = 0.5·L, esfuerzo axil N (tracción +) · combinación «C1: 1,0·D + 1,0·Hx»
A25: 11 | B25: Axil barra 6 (diagonal 2–3) | C25: kN | D25: =-8.53 | E25: -8.5355339 | F25: =E25-D25 | G25: =IF(ABS(D25)>0.000000000001,F25/D25,"—") | H25: 0 | I25: 0.011 | J25: =IF(ABS(F25)<=MAX(H25*ABS(D25),I25),"OK","NO") | K25: Publicado | L25: -8.53 | M25: Barra 6, en x = 0.5·L, esfuerzo axil N (tracción +) · combinación «C1: 1,0·D + 1,0·Hx»
B27: Comprobaciones dentro de tolerancia | D27: =COUNTIF(J15:J25,"OK") | E27: =ROWS(J15:J25) | F27: =IF(D27=E27,"VERIFICA","DIFIERE")
B28: Azul = dato ingresado o valor que entregó el programa (pegado); negro = fórmula de Excel. El valor «Programa» es el resultado del motor de cálculo de la app para el mismo modelo.

Sheet Ej A04
A1: A04 · Emparrillado en L empotrado en ambos extremos (flexión + torsión)
A2: Resultado publicado. Fuente: Univ. de Memphis, CIVL 7117 · capítulo 5b, ejemplo de emparrillado (apuntes de cátedra)
A3: https://www.ce.memphis.edu/7117/notes/presentations/chapter_05b.pdf
A4: Enunciado. Dos barras horizontales de 3 m en ángulo recto, unidas en el nudo 2 y empotradas en los extremos 1 y 3. Carga vertical de 22 kN hacia abajo en el nudo 2. E = 210 GPa, G = 84 GPa, I = 16,6·10⁻⁵ m⁴, J = 4,6·10⁻⁵ m⁴. La fuente publica v = −2,59 mm, giros de 0,00126 rad y esfuerzos de barra con tres cifras (algunos redondeados: por ejemplo el torsor); por eso las filas «publicado» tienen tolerancia mayor y se agregan las filas «solución exacta» deducidas por compatibilidad (θ = (P/4)·L²/(EI+GJ)).
A6: DATOS DEL EJERCICIO
A7: # | B7: Dato | C7: Unidad | D7: Valor | K7: Símbolo | L7: Fórmula (texto)
A8: 1 | B8: Módulo elástico | C8: MPa | D8: 210000 | K8: E | L8: dato ingresado
A9: 2 | B9: Módulo de corte | C9: MPa | D9: 84000 | K9: G | L9: dato ingresado
A10: 3 | B10: Inercia (16,6·10⁻⁵ m⁴) | C10: mm⁴ | D10: 166000000 | K10: I | L10: dato ingresado
A11: 4 | B11: Constante de torsión (4,6·10⁻⁵ m⁴) | C11: mm⁴ | D11: 46000000 | K11: J | L11: dato ingresado
A12: 5 | B12: Largo de cada barra | C12: mm | D12: 3000 | K12: L | L12: dato ingresado
A13: 6 | B13: Carga vertical en el nudo 2 | C13: kN | D13: 22 | K13: P | L13: dato ingresado
A14: 7 | B14: Giro exacto del nudo 2 (compatibilidad) | C14: rad | D14: =($D$13*1000/4)*$D$12^2/($D$8*$D$10+$D$9*$D$11) | K14: th | L14: valor = (P*1000/4)*L^2/(E*I+G*J)
A15: 8 | B15: Descenso exacto del nudo 2 | C15: mm | D15: =($D$13*1000/2)*$D$12^3/(12*$D$8*$D$10)+$D$14*$D$12/2 | K15: w | L15: valor = (P*1000/2)*L^3/(12*E*I)+th*L/2
A16: 9 | B16: Torsor exacto en cada barra | C16: kN·m | D16: =$D$9*$D$11*$D$14/$D$12/1000000 | K16: T | L16: valor = G*J*th/L/1000000
A18: COMPARACIÓN: TEORÍA / DATO PUBLICADO vs PROGRAMA (Atlas Estructuras 3D)
A19: # | B19: Comprobación | C19: Unidad | D19: Teoría / publicado | E19: Programa | F19: Diferencia (prog. − teoría) | G19: Error relativo | H19: Tol. relativa | I19: Tol. absoluta | J19: Estado | K19: Origen | L19: Expresión de la teoría (texto) | M19: Dónde se lee en el programa | N19: Nota
A20: 1 | B20: Descenso del nudo 2 (publicado) | C20: mm | D20: =-2.59 | E20: -2.6273983 | F20: =E20-D20 | G20: =IF(ABS(D20)>0.000000000001,F20/D20,"—") | H20: 0.02 | I20: 1e-06 | J20: =IF(ABS(F20)<=MAX(H20*ABS(D20),I20),"OK","NO") | K20: Publicado | L20: -2.59 | M20: Desplazamiento Uz del nudo 2 · combinación «C1: 1,0·D»
A21: 2 | B21: Giro del nudo 2 alrededor de X (publicado) | C21: rad | D21: =ABS(0.00126) | E21: 0.001278277 | F21: =E21-D21 | G21: =IF(ABS(D21)>0.000000000001,F21/D21,"—") | H21: 0.02 | I21: 1e-06 | J21: =IF(ABS(F21)<=MAX(H21*ABS(D21),I21),"OK","NO") | K21: Publicado | L21: 0.00126 | M21: Desplazamiento Rx del nudo 2 · combinación «C1: 1,0·D» | N21: Se comparan valores absolutos (la convención de signo es independiente del resultado).
A22: 3 | B22: Giro del nudo 2 alrededor de Y (publicado) | C22: rad | D22: =ABS(0.00126) | E22: 0.001278277 | F22: =E22-D22 | G22: =IF(ABS(D22)>0.000000000001,F22/D22,"—") | H22: 0.02 | I22: 1e-06 | J22: =IF(ABS(F22)<=MAX(H22*ABS(D22),I22),"OK","NO") | K22: Publicado | L22: 0.00126 | M22: Desplazamiento Ry del nudo 2 · combinación «C1: 1,0·D» | N22: Se comparan valores absolutos (la convención de signo es independiente del resultado).
A23: 4 | B23: Corte en el extremo 1 (publicado) | C23: kN | D23: =ABS(11.0) | E23: 11 | F23: =E23-D23 | G23: =IF(ABS(D23)>0.000000000001,F23/D23,"—") | H23: 0.001 | I23: 1e-06 | J23: =IF(ABS(F23)<=MAX(H23*ABS(D23),I23),"OK","NO") | K23: Publicado | L23: 11.0 | M23: Barra 1, en x = 0·L, corte Vy (en el plano del alma) · combinación «C1: 1,0·D» | N23: Se comparan valores absolutos (la convención de signo es independiente del resultado).
A24: 5 | B24: Momento flector en el empotramiento 1 (publicado) | C24: kN·m | D24: =ABS(31.0) | E24: 31.353579 | F24: =E24-D24 | G24: =IF(ABS(D24)>0.000000000001,F24/D24,"—") | H24: 0.02 | I24: 1e-06 | J24: =IF(ABS(F24)<=MAX(H24*ABS(D24),I24),"OK","NO") | K24: Publicado | L24: 31.0 | M24: Barra 1, en x = 0·L, momento flector Mz (eje fuerte) · combinación «C1: 1,0·D» | N24: Se comparan valores absolutos (la convención de signo es independiente del resultado).
A25: 6 | B25: Torsor en la barra 1 (publicado, redondeado en la fuente) | C25: kN·m | D25: =ABS(1.50) | E25: 1.6464208 | F25: =E25-D25 | G25: =IF(ABS(D25)>0.000000000001,F25/D25,"—") | H25: 0.1 | I25: 1e-06 | J25: =IF(ABS(F25)<=MAX(H25*ABS(D25),I25),"OK","NO") | K25: Publicado | L25: 1.50 | M25: Barra 1, en x = 0.5·L, torsor T · combinación «C1: 1,0·D» | N25: La fuente da 1,50; la solución exacta es 1,65 (fila siguiente). Se comparan valores absolutos (la convención de signo es independiente del resultado).
A26: 7 | B26: Descenso del nudo 2 (solución exacta) | C26: mm | D26: =-$D$15 | E26: -2.6273983 | F26: =E26-D26 | G26: =IF(ABS(D26)>0.000000000001,F26/D26,"—") | H26: 0.0001 | I26: 1e-06 | J26: =IF(ABS(F26)<=MAX(H26*ABS(D26),I26),"OK","NO") | K26: Fórmula | L26: -w | M26: Desplazamiento Uz del nudo 2 · combinación «C1: 1,0·D»
A27: 8 | B27: Giro del nudo 2 alrededor de X (solución exacta) | C27: rad | D27: =ABS($D$14) | E27: 0.001278277 | F27: =E27-D27 | G27: =IF(ABS(D27)>0.000000000001,F27/D27,"—") | H27: 0.0001 | I27: 1e-06 | J27: =IF(ABS(F27)<=MAX(H27*ABS(D27),I27),"OK","NO") | K27: Fórmula | L27: th | M27: Desplazamiento Rx del nudo 2 · combinación «C1: 1,0·D» | N27: Se comparan valores absolutos (la convención de signo es independiente del resultado).
A28: 9 | B28: Torsor en la barra 1 (solución exacta) | C28: kN·m | D28: =ABS($D$16) | E28: 1.6464208 | F28: =E28-D28 | G28: =IF(ABS(D28)>0.000000000001,F28/D28,"—") | H28: 0.0001 | I28: 1e-06 | J28: =IF(ABS(F28)<=MAX(H28*ABS(D28),I28),"OK","NO") | K28: Fórmula | L28: T | M28: Barra 1, en x = 0.5·L, torsor T · combinación «C1: 1,0·D» | N28: Se comparan valores absolutos (la convención de signo es independiente del resultado).
A29: 10 | B29: Reacción vertical en cada empotramiento | C29: kN | D29: =$D$13/2 | E29: 11 | F29: =E29-D29 | G29: =IF(ABS(D29)>0.000000000001,F29/D29,"—") | H29: 0.0001 | I29: 1e-06 | J29: =IF(ABS(F29)<=MAX(H29*ABS(D29),I29),"OK","NO") | K29: Fórmula | L29: P/2 | M29: Reacción Fz en el nudo 1 · combinación «C1: 1,0·D»
B31: Comprobaciones dentro de tolerancia | D31: =COUNTIF(J20:J29,"OK") | E31: =ROWS(J20:J29) | F31: =IF(D31=E31,"VERIFICA","DIFIERE")
B32: Azul = dato ingresado o valor que entregó el programa (pegado); negro = fórmula de Excel. El valor «Programa» es el resultado del motor de cálculo de la app para el mismo modelo.

Sheet Ej A05
A1: A05 · Barra traccionada IPB 120: resistencia por fluencia (ejemplo INTI-CIRSOC 4)
A2: Resultado publicado. Fuente: INTI-CIRSOC · «Ejemplos de aplicación del Reglamento CIRSOC 301-EL» (Ejemplos 4, 5 y 6)
A3: https://www.inti.gob.ar/assets/uploads/files/cirsoc/EJEMPLOS%202/EJEMPLOS%202.2/1_%20ejemplos_301.pdf
A4: Enunciado. Barra de acero F-24 (Fy = 235 MPa) con perfil IPB 120 (A = 34,0 cm²), L = 9,00 m y tracción mayorada Tu = 500 kN. El ejemplo publica la resistencia de diseño por fluencia de la sección bruta φt·Pn = 719 kN (φt = 0,90). Se comprueba además el axil y la relación de uso Tu/φt·Pn.
A5: Perfil. IPB 120 (tabla): h = 120 mm, b = 120 mm, tw = 6,5 mm, tf = 11 mm, A = 34,0 cm², Ix = 864 cm⁴, Iy = 318 cm⁴.
A7: DATOS DEL EJERCICIO
A8: # | B8: Dato | C8: Unidad | D8: Valor | K8: Símbolo | L8: Fórmula (texto)
A9: 1 | B9: Módulo elástico | C9: MPa | D9: 200000 | K9: E | L9: dato ingresado
A10: 2 | B10: Tensión de fluencia F-24 | C10: MPa | D10: 235 | K10: Fy | L10: dato ingresado
A11: 3 | B11: Área bruta IPB 120 | C11: mm² | D11: 3400 | K11: A | L11: dato ingresado
A12: 4 | B12: Largo de la barra | C12: mm | D12: 9000 | K12: L | L12: dato ingresado
A13: 5 | B13: Tracción mayorada (publicada) | C13: kN | D13: 500 | K13: Tu | L13: dato ingresado
A14: 6 | B14: φt·Pn = 0,90·Fy·Ag | C14: kN | D14: =0.9*$D$10*$D$11/1000 | K14: phiPt | L14: valor = 0.9*Fy*A/1000
A16: COMPARACIÓN: TEORÍA / DATO PUBLICADO vs PROGRAMA (Atlas Estructuras 3D)
A17: # | B17: Comprobación | C17: Unidad | D17: Teoría / publicado | E17: Programa | F17: Diferencia (prog. − teoría) | G17: Error relativo | H17: Tol. relativa | I17: Tol. absoluta | J17: Estado | K17: Origen | L17: Expresión de la teoría (texto) | M17: Dónde se lee en el programa | N17: Nota
A18: 1 | B18: Resistencia de diseño por fluencia φt·Pn (publicada) | C18: kN | D18: =719 | E18: 719.1 | F18: =E18-D18 | G18: =IF(ABS(D18)>0.000000000001,F18/D18,"—") | H18: 0.001 | I18: 1e-06 | J18: =IF(ABS(F18)<=MAX(H18*ABS(D18),I18),"OK","NO") | K18: Publicado | L18: 719 | M18: Barra 1: φt·Pn tracción (verificación de perfiles) | N18: La fuente redondea a 719 kN; la fórmula da 719,1 kN.
A19: 2 | B19: Resistencia de diseño φt·Pn (fórmula 0,90·Fy·Ag) | C19: kN | D19: =$D$14 | E19: 719.1 | F19: =E19-D19 | G19: =IF(ABS(D19)>0.000000000001,F19/D19,"—") | H19: 0.001 | I19: 1e-06 | J19: =IF(ABS(F19)<=MAX(H19*ABS(D19),I19),"OK","NO") | K19: Fórmula | L19: phiPt | M19: Barra 1: φt·Pn tracción (verificación de perfiles)
A20: 3 | B20: Esfuerzo axil en la barra (tracción +) | C20: kN | D20: =$D$13 | E20: 500 | F20: =E20-D20 | G20: =IF(ABS(D20)>0.000000000001,F20/D20,"—") | H20: 0.001 | I20: 1e-06 | J20: =IF(ABS(F20)<=MAX(H20*ABS(D20),I20),"OK","NO") | K20: Fórmula | L20: Tu | M20: Barra 1, en x = 0.5·L, esfuerzo axil N (tracción +) · combinación «C1: Tu mayorada»
A21: 4 | B21: Reacción horizontal en el apoyo fijo | C21: kN | D21: =-$D$13 | E21: -500 | F21: =E21-D21 | G21: =IF(ABS(D21)>0.000000000001,F21/D21,"—") | H21: 0.001 | I21: 1e-06 | J21: =IF(ABS(F21)<=MAX(H21*ABS(D21),I21),"OK","NO") | K21: Fórmula | L21: -Tu | M21: Reacción Fx en el nudo 1 · combinación «C1: Tu mayorada»
A22: 5 | B22: Relación de uso Tu / φt·Pn | D22: =$D$13/$D$14 | E22: 0.69531359 | F22: =E22-D22 | G22: =IF(ABS(D22)>0.000000000001,F22/D22,"—") | H22: 0.001 | I22: 1e-06 | J22: =IF(ABS(F22)<=MAX(H22*ABS(D22),I22),"OK","NO") | K22: Fórmula | L22: Tu/phiPt | M22: Barra 1: relación de uso r máxima entre combinaciones de resistencia
B24: Comprobaciones dentro de tolerancia | D24: =COUNTIF(J18:J22,"OK") | E24: =ROWS(J18:J22) | F24: =IF(D24=E24,"VERIFICA","DIFIERE")
B25: Azul = dato ingresado o valor que entregó el programa (pegado); negro = fórmula de Excel. El valor «Programa» es el resultado del motor de cálculo de la app para el mismo modelo.

Sheet Ej A06
A1: A06 · Viga IPE 500 de 16 m: esfuerzos mayorados 1,2D + 1,6L (ejemplo INTI-CIRSOC 5)
A2: Resultado publicado. Fuente: INTI-CIRSOC · «Ejemplos de aplicación del Reglamento CIRSOC 301-EL» (Ejemplos 4, 5 y 6)
A3: https://www.inti.gob.ar/assets/uploads/files/cirsoc/EJEMPLOS%202/EJEMPLOS%202.2/1_%20ejemplos_301.pdf
A4: Enunciado. Viga biapoyada de 16,00 m con D = 2 kN/m y L = 5 kN/m. El ejemplo calcula qu = 1,2D + 1,6L = 10,4 kN/m, el momento máximo Mu = 332,8 kN·m, y en la sección del empalme (x = 4 m) un momento Mf + Mw = 194,17 + 55,43 = 249,60 kN·m y un corte Vu = 41,6 kN. Se verifica que el programa, con la combinación U2, entregue los mismos esfuerzos.
A5: Perfil. IPE 500 (tabla): h = 500 mm, b = 200 mm, tw = 10,2 mm, tf = 16 mm, A = 116 cm², Ix = 48 200 cm⁴, Iy = 2 140 cm⁴.
A7: DATOS DEL EJERCICIO
A8: # | B8: Dato | C8: Unidad | D8: Valor | K8: Símbolo | L8: Fórmula (texto)
A9: 1 | B9: Módulo elástico | C9: MPa | D9: 200000 | K9: E | L9: dato ingresado
A10: 2 | B10: Luz | C10: mm | D10: 16000 | K10: L | L10: dato ingresado
A11: 3 | B11: Carga permanente | C11: kN/m | D11: 2 | K11: qD | L11: dato ingresado
A12: 4 | B12: Sobrecarga | C12: kN/m | D12: 5 | K12: qL | L12: dato ingresado
A13: 5 | B13: Sección del empalme | C13: mm | D13: 4000 | K13: xs | L13: dato ingresado
A14: 6 | B14: Carga mayorada | C14: kN/m | D14: =1.2*$D$11+1.6*$D$12 | K14: qu | L14: valor = 1.2*qD+1.6*qL
A15: 7 | B15: Momento máximo | C15: kN·m | D15: =$D$14*$D$10^2/8/1000000 | K15: Mu | L15: valor = qu*L^2/8/1000000
A16: 8 | B16: Momento en x = 4 m | C16: kN·m | D16: =$D$14*$D$13*($D$10-$D$13)/2/1000000 | K16: Ms | L16: valor = qu*xs*(L-xs)/2/1000000
A17: 9 | B17: Corte en x = 4 m | C17: kN | D17: =$D$14*($D$10/2-$D$13)/1000 | K17: Vs | L17: valor = qu*(L/2-xs)/1000
A19: COMPARACIÓN: TEORÍA / DATO PUBLICADO vs PROGRAMA (Atlas Estructuras 3D)
A20: # | B20: Comprobación | C20: Unidad | D20: Teoría / publicado | E20: Programa | F20: Diferencia (prog. − teoría) | G20: Error relativo | H20: Tol. relativa | I20: Tol. absoluta | J20: Estado | K20: Origen | L20: Expresión de la teoría (texto) | M20: Dónde se lee en el programa | N20: Nota
A21: 1 | B21: Momento máximo Mu en el centro (publicado) | C21: kN·m | D21: =ABS(332.8) | E21: 332.8 | F21: =E21-D21 | G21: =IF(ABS(D21)>0.000000000001,F21/D21,"—") | H21: 0.0001 | I21: 1e-06 | J21: =IF(ABS(F21)<=MAX(H21*ABS(D21),I21),"OK","NO") | K21: Publicado | L21: 332.8 | M21: Barra 1, en x = 0.5·L, momento flector Mz (eje fuerte) · combinación «U2: 1,2D+1,6L» | N21: Se comparan valores absolutos (la convención de signo es independiente del resultado).
A22: 2 | B22: Momento en la sección del empalme, Mf + Mw (publicado) | C22: kN·m | D22: =ABS(194.17+55.43) | E22: 249.6 | F22: =E22-D22 | G22: =IF(ABS(D22)>0.000000000001,F22/D22,"—") | H22: 0.0001 | I22: 1e-06 | J22: =IF(ABS(F22)<=MAX(H22*ABS(D22),I22),"OK","NO") | K22: Publicado | L22: 194.17+55.43 | M22: Barra 1, en x = 0.25·L, momento flector Mz (eje fuerte) · combinación «U2: 1,2D+1,6L» | N22: Se comparan valores absolutos (la convención de signo es independiente del resultado).
A23: 3 | B23: Corte Vu en la sección del empalme (publicado) | C23: kN | D23: =ABS(41.6) | E23: 41.6 | F23: =E23-D23 | G23: =IF(ABS(D23)>0.000000000001,F23/D23,"—") | H23: 0.0001 | I23: 1e-06 | J23: =IF(ABS(F23)<=MAX(H23*ABS(D23),I23),"OK","NO") | K23: Publicado | L23: 41.6 | M23: Barra 1, en x = 0.25·L, corte Vy (en el plano del alma) · combinación «U2: 1,2D+1,6L» | N23: Se comparan valores absolutos (la convención de signo es independiente del resultado).
A24: 4 | B24: Reacción en el apoyo A | C24: kN | D24: =$D$14*$D$10/2000 | E24: 83.2 | F24: =E24-D24 | G24: =IF(ABS(D24)>0.000000000001,F24/D24,"—") | H24: 0.0001 | I24: 1e-06 | J24: =IF(ABS(F24)<=MAX(H24*ABS(D24),I24),"OK","NO") | K24: Fórmula | L24: qu*L/2000 | M24: Reacción Fz en el nudo 1 · combinación «U2: 1,2D+1,6L»
B26: Comprobaciones dentro de tolerancia | D26: =COUNTIF(J21:J24,"OK") | E26: =ROWS(J21:J24) | F26: =IF(D26=E26,"VERIFICA","DIFIERE")
B27: Azul = dato ingresado o valor que entregó el programa (pegado); negro = fórmula de Excel. El valor «Programa» es el resultado del motor de cálculo de la app para el mismo modelo.

Sheet Ej A07
A1: A07 · Viga PNI 300 de 10 m: momento mayorado y resistencia φb·Mp (ejemplo INTI-CIRSOC 6)
A2: Resultado publicado. Fuente: INTI-CIRSOC · «Ejemplos de aplicación del Reglamento CIRSOC 301-EL» (Ejemplos 4, 5 y 6)
A3: https://www.inti.gob.ar/assets/uploads/files/cirsoc/EJEMPLOS%202/EJEMPLOS%202.2/1_%20ejemplos_301.pdf
A4: Enunciado. Viga biapoyada de 10,00 m con carga mayorada qu = 22 kN/m, de acero F-24 (Fy = 235 MPa), con arriostramiento lateral continuo (Lb ≤ Lp). El ejemplo publica Mu = 275 kN·m y la resistencia del perfil solo φb·Mp = 161,16 kN·m (Zx de tabla = 762 cm³), por lo que agrega una platabanda (esa parte no puede reproducirse con el modelo de secciones del programa). El programa estima el módulo plástico con la geometría simplificada de la sección, que en el PNI 300 resulta 0,8 % mayor que el de tabla; por eso la fila de resistencia admite 1,5 %.
A5: Perfil. PNI 300 (IPN 300, tabla): h = 300 mm, b = 125 mm, tw = 10,8 mm, tf = 16,2 mm (medio), A = 69,1 cm², Ix = 9 800 cm⁴, Iy = 451 cm⁴, Wx = 653 cm³, Zx = 762 cm³.
A7: DATOS DEL EJERCICIO
A8: # | B8: Dato | C8: Unidad | D8: Valor | K8: Símbolo | L8: Fórmula (texto)
A9: 1 | B9: Módulo elástico | C9: MPa | D9: 200000 | K9: E | L9: dato ingresado
A10: 2 | B10: Tensión de fluencia F-24 | C10: MPa | D10: 235 | K10: Fy | L10: dato ingresado
A11: 3 | B11: Luz | C11: mm | D11: 10000 | K11: L | L11: dato ingresado
A12: 4 | B12: Carga mayorada (publicada) | C12: kN/m | D12: 22 | K12: qu | L12: dato ingresado
A13: 5 | B13: Momento máximo | C13: kN·m | D13: =$D$12*$D$11^2/8/1000000 | K13: Mu | L13: valor = qu*L^2/8/1000000
A14: 6 | B14: Módulo plástico de tabla | C14: mm³ | D14: 762000 | K14: Zx | L14: dato ingresado
A15: 7 | B15: φb·Mp con el Zx de tabla (publicado: 161,16) | C15: kN·m | D15: =0.9*$D$10*$D$14/1000000 | K15: phiMp | L15: valor = 0.9*Fy*Zx/1000000
A17: COMPARACIÓN: TEORÍA / DATO PUBLICADO vs PROGRAMA (Atlas Estructuras 3D)
A18: # | B18: Comprobación | C18: Unidad | D18: Teoría / publicado | E18: Programa | F18: Diferencia (prog. − teoría) | G18: Error relativo | H18: Tol. relativa | I18: Tol. absoluta | J18: Estado | K18: Origen | L18: Expresión de la teoría (texto) | M18: Dónde se lee en el programa | N18: Nota
A19: 1 | B19: Momento máximo Mu (publicado) | C19: kN·m | D19: =ABS(275) | E19: 275 | F19: =E19-D19 | G19: =IF(ABS(D19)>0.000000000001,F19/D19,"—") | H19: 0.0001 | I19: 1e-06 | J19: =IF(ABS(F19)<=MAX(H19*ABS(D19),I19),"OK","NO") | K19: Publicado | L19: 275 | M19: Barra 1, en x = 0.5·L, momento flector Mz (eje fuerte) · combinación «C1: qu mayorada» | N19: Se comparan valores absolutos (la convención de signo es independiente del resultado).
A20: 2 | B20: Corte máximo en el apoyo | C20: kN | D20: =ABS($D$12*$D$11/2000) | E20: 110 | F20: =E20-D20 | G20: =IF(ABS(D20)>0.000000000001,F20/D20,"—") | H20: 0.0001 | I20: 1e-06 | J20: =IF(ABS(F20)<=MAX(H20*ABS(D20),I20),"OK","NO") | K20: Fórmula | L20: qu*L/2000 | M20: Barra 1, en x = 0·L, corte Vy (en el plano del alma) · combinación «C1: qu mayorada» | N20: Se comparan valores absolutos (la convención de signo es independiente del resultado).
A21: 3 | B21: Resistencia de diseño φb·Mp del perfil solo (publicada) | C21: kN·m | D21: =161.16 | E21: 162.44075 | F21: =E21-D21 | G21: =IF(ABS(D21)>0.000000000001,F21/D21,"—") | H21: 0.015 | I21: 1e-06 | J21: =IF(ABS(F21)<=MAX(H21*ABS(D21),I21),"OK","NO") | K21: Publicado | L21: 161.16 | M21: Barra 1: φb·Mn flexión eje fuerte (verificación de perfiles) | N21: El programa calcula Zx = 768 cm³ con la geometría simplificada (tabla: 762 cm³): +0,8 %, del lado inseguro pero dentro de la tolerancia.
A22: 4 | B22: Relación de uso Mu / φb·Mp (publicada 275/161,16) | D22: =275/161.16 | E22: 1.692925 | F22: =E22-D22 | G22: =IF(ABS(D22)>0.000000000001,F22/D22,"—") | H22: 0.015 | I22: 1e-06 | J22: =IF(ABS(F22)<=MAX(H22*ABS(D22),I22),"OK","NO") | K22: Publicado | L22: 275/161.16 | M22: Barra 1: relación de uso r máxima entre combinaciones de resistencia | N22: Mayor que 1: el perfil solo no alcanza, por eso el ejemplo agrega la platabanda.
B24: Comprobaciones dentro de tolerancia | D24: =COUNTIF(J19:J22,"OK") | E24: =ROWS(J19:J22) | F24: =IF(D24=E24,"VERIFICA","DIFIERE")
B25: Azul = dato ingresado o valor que entregó el programa (pegado); negro = fórmula de Excel. El valor «Programa» es el resultado del motor de cálculo de la app para el mismo modelo.

Sheet Ej A08
A1: A08 · Columna W14×74, A36, KL = 20 ft: resistencia a compresión (apuntes MSU, ej. 3.2)
A2: Resultado publicado. Fuente: Michigan State Univ., CE 405 «Design of Steel Structures», cap. 3 «Compression members» (ejemplos 3.2 y 3.4, AISC-LRFD 1999)
A3: https://www.egr.msu.edu/~harichan/classes/ce405/chap3.pdf
A4: Enunciado. Columna W14×74 de acero A36 (Fy = 36 ksi, E = 29 000 ksi) con KL = 20 ft = 240 in en ambos ejes. El ejemplo obtiene KL/ry = 240/2,48 = 96,77 (gobierna el eje débil), λc = 1,085, Fcr = 21,99 ksi y φcPn = 408 kip con φc = 0,85, que es el factor del CIRSOC 301-2005. Se ingresa la sección con los datos de la tabla AISC (las inercias son coherentes con los radios de giro publicados) y se compara.
A5: Perfil. W14×74 (tabla AISC): d = 14,17 in, bf = 10,07 in, tw = 0,450 in, tf = 0,785 in, A = 21,8 in², Ix = 796 in⁴, Iy = 134 in⁴, rx = 6,04 in, ry = 2,48 in, J = 3,87 in⁴. Unidades del programa: mm, N, MPa (1 in = 25,4 mm; 1 ksi = 6,894757 MPa; 1 kip = 4,4482216 kN).
A7: DATOS DEL EJERCICIO
A8: # | B8: Dato | C8: Unidad | D8: Valor | K8: Símbolo | L8: Fórmula (texto)
A9: 1 | B9: Módulo elástico | C9: ksi | D9: 29000 | K9: E_ksi | L9: dato ingresado
A10: 2 | B10: Tensión de fluencia A36 | C10: ksi | D10: 36 | K10: Fy_ksi | L10: dato ingresado
A11: 3 | B11: Área | C11: in² | D11: 21.8 | K11: A_in2 | L11: dato ingresado
A12: 4 | B12: Radio de giro fuerte (tabla) | C12: in | D12: 6.04 | K12: rx | L12: dato ingresado
A13: 5 | B13: Radio de giro débil (tabla) | C13: in | D13: 2.48 | K13: ry | L13: dato ingresado
A14: 6 | B14: Longitud efectiva en ambos ejes (publicada) | C14: in | D14: 240 | K14: KL | L14: dato ingresado
A15: 7 | B15: Carga axil mayorada adoptada para la relación de uso | C15: kip | D15: 300 | K15: Pu_kip | L15: dato ingresado
A16: 8 | B16: Módulo elástico en MPa | C16: MPa | D16: =$D$9*6.894757 | K16: E | L16: valor = E_ksi*6.894757
A17: 9 | B17: Fluencia en MPa | C17: MPa | D17: =$D$10*6.894757 | K17: Fy | L17: valor = Fy_ksi*6.894757
A18: 10 | B18: Módulo de corte (no interviene en el resultado) | C18: MPa | D18: =$D$16/2.6 | K18: G | L18: valor = E/2.6
A19: 11 | B19: Longitud efectiva en mm | C19: mm | D19: =$D$14*25.4 | K19: KLmm | L19: valor = KL*25.4
A20: 12 | B20: Carga axil mayorada | C20: kN | D20: =$D$15*4.4482216 | K20: Pu | L20: valor = Pu_kip*4.4482216
A21: 13 | B21: λc del eje débil (publicado: 1,085) | D21: =$D$14/$D$13/PI()*SQRT($D$10/$D$9) | K21: lamy | L21: valor = KL/ry/PI()*SQRT(Fy_ksi/E_ksi)
A22: 14 | B22: λc del eje fuerte | D22: =$D$14/$D$12/PI()*SQRT($D$10/$D$9) | K22: lamx | L22: valor = KL/rx/PI()*SQRT(Fy_ksi/E_ksi)
A23: 15 | B23: λc gobernante | D23: =MAX($D$22,$D$21) | K23: lamc | L23: valor = MAX(lamx,lamy)
A24: 16 | B24: Tensión crítica (publicada: 21,99 ksi) | C24: ksi | D24: =IF($D$23<=1.5,0.658^($D$23^2),0.877/$D$23^2)*$D$10 | K24: Fcr | L24: valor = IF(lamc<=1.5,0.658^(lamc^2),0.877/lamc^2)*Fy_ksi
A25: 17 | B25: φc·Pn recalculado con la fórmula del libro | C25: kip | D25: =0.85*$D$11*$D$24 | K25: phiPn | L25: valor = 0.85*A_in2*Fcr
A26: 18 | B26: φc·Pn en kN | C26: kN | D26: =$D$25*4.4482216 | K26: phiPnkN | L26: valor = phiPn*4.4482216
A28: COMPARACIÓN: TEORÍA / DATO PUBLICADO vs PROGRAMA (Atlas Estructuras 3D)
A29: # | B29: Comprobación | C29: Unidad | D29: Teoría / publicado | E29: Programa | F29: Diferencia (prog. − teoría) | G29: Error relativo | H29: Tol. relativa | I29: Tol. absoluta | J29: Estado | K29: Origen | L29: Expresión de la teoría (texto) | M29: Dónde se lee en el programa | N29: Nota
